2025-04-07 10:08:49,080 INFO    MainThread:23704 [wandb_setup.py:_flush():79] Current SDK version is 0.18.5
2025-04-07 10:08:49,080 INFO    MainThread:23704 [wandb_setup.py:_flush():79] Configure stats pid to 23704
2025-04-07 10:08:49,080 INFO    MainThread:23704 [wandb_setup.py:_flush():79] Loading settings from C:\Users\PC MASTER\.config\wandb\settings
2025-04-07 10:08:49,080 INFO    MainThread:23704 [wandb_setup.py:_flush():79] Loading settings from C:\Users\PC MASTER\desktop\ucreativa-ai\07-FUNDAMENTOS DE DEEP LEARNING Y APRENDIZAJE AUTOMÁTICO\S02\hydra_wandb\wandb\settings
2025-04-07 10:08:49,080 INFO    MainThread:23704 [wandb_setup.py:_flush():79] Loading settings from environment variables: {}
2025-04-07 10:08:49,080 INFO    MainThread:23704 [wandb_setup.py:_flush():79] Applying setup settings: {'mode': None, '_disable_service': None}
2025-04-07 10:08:49,082 INFO    MainThread:23704 [wandb_setup.py:_flush():79] Inferring run settings from compute environment: {'program': '<python with no main file>'}
2025-04-07 10:08:49,082 INFO    MainThread:23704 [wandb_setup.py:_flush():79] Applying login settings: {}
2025-04-07 10:08:49,083 INFO    MainThread:23704 [wandb_init.py:_log_setup():534] Logging user logs to C:\Users\PC MASTER\desktop\ucreativa-ai\07-FUNDAMENTOS DE DEEP LEARNING Y APRENDIZAJE AUTOMÁTICO\S02\hydra_wandb\wandb\run-20250407_100849-8huvdv46\logs\debug.log
2025-04-07 10:08:49,083 INFO    MainThread:23704 [wandb_init.py:_log_setup():535] Logging internal logs to C:\Users\PC MASTER\desktop\ucreativa-ai\07-FUNDAMENTOS DE DEEP LEARNING Y APRENDIZAJE AUTOMÁTICO\S02\hydra_wandb\wandb\run-20250407_100849-8huvdv46\logs\debug-internal.log
2025-04-07 10:08:49,083 INFO    MainThread:23704 [wandb_init.py:init():621] calling init triggers
2025-04-07 10:08:49,083 INFO    MainThread:23704 [wandb_init.py:init():628] wandb.init called with sweep_config: {}
config: {'project': {'name': 'my_hydra_wandb_project', 'run_name': 'test_run'}, 'model': {'type': 'logistic', 'C': 1.0, 'max_iter': 100}}
2025-04-07 10:08:49,083 INFO    MainThread:23704 [wandb_init.py:init():671] starting backend
2025-04-07 10:08:49,083 INFO    MainThread:23704 [wandb_init.py:init():675] sending inform_init request
2025-04-07 10:08:49,085 INFO    MainThread:23704 [backend.py:_multiprocessing_setup():104] multiprocessing start_methods=spawn, using: spawn
2025-04-07 10:08:49,085 INFO    MainThread:23704 [wandb_init.py:init():688] backend started and connected
2025-04-07 10:08:49,088 INFO    MainThread:23704 [wandb_run.py:_label_probe_notebook():1342] probe notebook
2025-04-07 10:08:49,088 INFO    MainThread:23704 [wandb_run.py:_label_probe_notebook():1352] Unable to probe notebook: 'NoneType' object has no attribute 'get'
2025-04-07 10:08:49,088 INFO    MainThread:23704 [wandb_init.py:init():783] updated telemetry
2025-04-07 10:08:49,166 INFO    MainThread:23704 [wandb_init.py:init():816] communicating run to backend with 90.0 second timeout
2025-04-07 10:10:19,938 ERROR   MainThread:23704 [wandb_init.py:init():842] encountered error: Run initialization has timed out after 90.0 sec. 
Please refer to the documentation for additional information: https://docs.wandb.ai/guides/track/tracking-faq#initstarterror-error-communicating-with-wandb-process-
2025-04-07 10:10:19,938 ERROR   MainThread:23704 [wandb_init.py:init():1266] error in wandb.init()
Traceback (most recent call last):
  File "C:\Users\PC MASTER\AppData\Local\Programs\Python\Python310\lib\site-packages\wandb\sdk\wandb_init.py", line 1256, in init
    return wi.init()
  File "C:\Users\PC MASTER\AppData\Local\Programs\Python\Python310\lib\site-packages\wandb\sdk\wandb_init.py", line 848, in init
    raise error
wandb.errors.errors.CommError: Run initialization has timed out after 90.0 sec. 
Please refer to the documentation for additional information: https://docs.wandb.ai/guides/track/tracking-faq#initstarterror-error-communicating-with-wandb-process-
2025-04-07 10:14:57,355 WARNING MsgRouterThr:23704 [router.py:message_loop():77] message_loop has been closed
2025-04-07 10:14:57,355 WARNING MsgRouterThr:23704 [router.py:message_loop():77] message_loop has been closed
